const x = 10

try {
    x = 2
} catch(err) {
    console.log(`Erro: ${err}`)
}

//  O try catch pode fazer com que a excução do projeto não seja fechada